g0404400@sf3:~/python[509]$ graph_server.py 3333
waiting for new connection on port 3333
accepted connection from 127.0.0.1:57929
add
dddd
ddd
ddd
fddd


.
dfddfdd
connection with 127.0.0.1 closed.
g0404400@sf3:~/python[510]$ ddd
ddd: Interrupted system call

Internal error (Segmentation Fault).

Oops!  You have found a bug in DDD.

If you can reproduce this bug, please send a bug report
to <bug-ddd@gnu.org>, giving a subject like

    DDD 3.3 (sparc-sun-solaris2.7) gets `Segmentation Fault' signal

To enable us to fix the bug, you should include the following information:
* What you were doing to get this message.  Report all the facts.
* The contents of the `~/.ddd/log' file as generated by this session.
Please read also the section "Reporting Bugs" in the DDD manual.

We thank you for your support.

Segmentation Fault
